Workbook

Sheet Billed and Net Gen
A1: Billed sales and net generation, monthly FY2026 to FY2028
A2: GWh. Losses = net generation less billed sales; loss % is losses as a share of net generation. Blue cells are inputs; the rest is calculated.
A4: Period | B4: Basis | C4: Billed sales (GWh) | D4: Loss % of net gen | E4: Losses (GWh) | F4: Net generation (GWh)
A5: Jan 2026 | B5: Actual | C5: ='Billed by rate class'!B11 | D5: =E5/F5 | E5: =F5-C5 | F5: 325.445
A6: Feb 2026 | B6: Actual | C6: ='Billed by rate class'!C11 | D6: =E6/F6 | E6: =F6-C6 | F6: 294.13183
A7: Mar 2026 | B7: Actual | C7: ='Billed by rate class'!D11 | D7: =E7/F7 | E7: =F7-C7 | F7: 346.44413
A8: Apr 2026 | B8: Actual | C8: ='Billed by rate class'!E11 | D8: =E8/F8 | E8: =F8-C8 | F8: 346.20891
A9: May 2026 | B9: Actual | C9: ='Billed by rate class'!F11 | D9: =E9/F9 | E9: =F9-C9 | F9: 395.07701
A10: Jun 2026 | B10: Actual | C10: ='Billed by rate class'!G11 | D10: =E10/F10 | E10: =F10-C10 | F10: 391.36884
A11: Jul 2026 | B11: Actual | C11: ='Billed by rate class'!H11 | D11: =E11/F11 | E11: =F11-C11 | F11: 427.85241
A12: Aug 2026 | B12: Actual | C12: ='Billed by rate class'!I11 | D12: =E12/F12 | E12: =F12-C12 | F12: 426.05551
A13: Sep 2026 | B13: Billed actual, net gen estimate | C13: ='Billed by rate class'!J11 | D13: =E13/F13 | E13: =F13-C13 | F13: 407.689
A14: Oct 2026 | B14: Forecast | C14: ='Billed by rate class'!K11 | D14: =E14/F14 | E14: =F14-C14 | F14: 397.45819
A15: Nov 2026 | B15: Forecast | C15: ='Billed by rate class'!L11 | D15: =E15/F15 | E15: =F15-C15 | F15: 390.32472
A16: Dec 2026 | B16: Forecast | C16: ='Billed by rate class'!M11 | D16: =E16/F16 | E16: =F16-C16 | F16: 378.89464
A17: FY2026 | C17: =SUM(C5:C16) | D17: =E17/F17 | E17: =SUM(E5:E16) | F17: =SUM(F5:F16)
A18: Per financials LE | C18: 3299.661 | D18: =E18/F18 | E18: =F18-C18 | F18: 4526.9502
A19: Difference | C19: =C17-C18 | E19: =E17-E18 | F19: =F17-F18
A21: Jan 2027 | B21: Forecast | C21: ='Billed by rate class'!O11 | D21: 0.2775 | E21: =C21*D21/(1-D21) | F21: =C21+E21
A22: Feb 2027 | B22: Forecast | C22: ='Billed by rate class'!P11 | D22: 0.2278 | E22: =C22*D22/(1-D22) | F22: =C22+E22
A23: Mar 2027 | B23: Forecast | C23: ='Billed by rate class'!Q11 | D23: 0.2934 | E23: =C23*D23/(1-D23) | F23: =C23+E23
A24: Apr 2027 | B24: Forecast | C24: ='Billed by rate class'!R11 | D24: 0.2739 | E24: =C24*D24/(1-D24) | F24: =C24+E24
A25: May 2027 | B25: Forecast | C25: ='Billed by rate class'!S11 | D25: 0.3072 | E25: =C25*D25/(1-D25) | F25: =C25+E25
A26: Jun 2027 | B26: Forecast | C26: ='Billed by rate class'!T11 | D26: 0.2653 | E26: =C26*D26/(1-D26) | F26: =C26+E26
A27: Jul 2027 | B27: Forecast | C27: ='Billed by rate class'!U11 | D27: 0.2756 | E27: =C27*D27/(1-D27) | F27: =C27+E27
A28: Aug 2027 | B28: Forecast | C28: ='Billed by rate class'!V11 | D28: 0.2821 | E28: =C28*D28/(1-D28) | F28: =C28+E28
A29: Sep 2027 | B29: Forecast | C29: ='Billed by rate class'!W11 | D29: 0.2535 | E29: =C29*D29/(1-D29) | F29: =C29+E29
A30: Oct 2027 | B30: Forecast | C30: ='Billed by rate class'!X11 | D30: 0.2545 | E30: =C30*D30/(1-D30) | F30: =C30+E30
A31: Nov 2027 | B31: Forecast | C31: ='Billed by rate class'!Y11 | D31: 0.2475 | E31: =C31*D31/(1-D31) | F31: =C31+E31
A32: Dec 2027 | B32: Forecast | C32: ='Billed by rate class'!Z11 | D32: 0.2834 | E32: =C32*D32/(1-D32) | F32: =C32+E32
A33: FY2027 | C33: =SUM(C21:C32) | D33: =E33/F33 | E33: =SUM(E21:E32) | F33: =SUM(F21:F32)
A35: Jan 2028 | B35: Forecast | C35: ='Billed by rate class'!AB11 | D35: 0.2777 | E35: =C35*D35/(1-D35) | F35: =C35+E35
A36: Feb 2028 | B36: Forecast | C36: ='Billed by rate class'!AC11 | D36: 0.2281 | E36: =C36*D36/(1-D36) | F36: =C36+E36
A37: Mar 2028 | B37: Forecast | C37: ='Billed by rate class'!AD11 | D37: 0.2933 | E37: =C37*D37/(1-D37) | F37: =C37+E37
A38: Apr 2028 | B38: Forecast | C38: ='Billed by rate class'!AE11 | D38: 0.2738 | E38: =C38*D38/(1-D38) | F38: =C38+E38
A39: May 2028 | B39: Forecast | C39: ='Billed by rate class'!AF11 | D39: 0.3071 | E39: =C39*D39/(1-D39) | F39: =C39+E39
A40: Jun 2028 | B40: Forecast | C40: ='Billed by rate class'!AG11 | D40: 0.2652 | E40: =C40*D40/(1-D40) | F40: =C40+E40
A41: Jul 2028 | B41: Forecast | C41: ='Billed by rate class'!AH11 | D41: 0.2756 | E41: =C41*D41/(1-D41) | F41: =C41+E41
A42: Aug 2028 | B42: Forecast | C42: ='Billed by rate class'!AI11 | D42: 0.2821 | E42: =C42*D42/(1-D42) | F42: =C42+E42
A43: Sep 2028 | B43: Forecast | C43: ='Billed by rate class'!AJ11 | D43: 0.2535 | E43: =C43*D43/(1-D43) | F43: =C43+E43
...

Sheet Billed by rate class
A1: Billed sales by rate class, FY2026 to FY2028 (GWh)
A2: January to September 2026 actual. October to December 2026 is set so FY2026 equals the financials LE. 2027 and 2028 per the register.
A4: Rate class | B4: Jan 26 | C4: Feb 26 | D4: Mar 26 | E4: Apr 26 | F4: May 26 | G4: Jun 26 | H4: Jul 26 | I4: Aug 26 | J4: Sep 26 | K4: Oct 26 | L4: Nov 26 | M4: Dec 26 | N4: FY2026 | O4: Jan 27 | P4: Feb 27 | Q4: Mar 27 | R4: Apr 27 | S4: May 27 | T4: Jun 27 | U4: Jul 27 | V4: Aug 27 | W4: Sep 27 | X4: Oct 27 | Y4: Nov 27 | Z4: Dec 27 | AA4: FY2027 | AB4: Jan 28 | AC4: Feb 28 | AD4: Mar 28 | AE4: Apr 28 | AF4: May 28 | AG4: Jun 28 | AH4: Jul 28 | AI4: Aug 28 | AJ4: Sep 28 | AK4: Oct 28 | AL4: Nov 28 | AM4: Dec 28 | AN4: FY2028
A5: RT10 Residential | B5: 84.427346 | C5: 76.489141 | D5: 88.277732 | E5: 87.175653 | F5: 99.081407 | G5: 101.30012 | H5: 113.61299 | I5: 117.67104 | J5: 114.56597 | K5: 115.26654 | L5: 113.31766 | M5: 111.57915 | N5: =SUM(B5:M5) | O5: 99.48207 | P5: 94.597041 | Q5: 97.684066 | R5: 97.876011 | S5: 103.62266 | T5: 110.79494 | U5: 115.53343 | V5: 122.14158 | W5: 118.21914 | X5: 112.53588 | Y5: 98.622924 | Z5: 103.89025 | AA5: =SUM(O5:Z5) | AB5: 103.45557 | AC5: 96.409453 | AD5: 100.66028 | AE5: 100.54014 | AF5: 106.06658 | AG5: 113.92291 | AH5: 118.73436 | AI5: 125.62747 | AJ5: 121.46688 | AK5: 115.40248 | AL5: 100.66577 | AM5: 106.34809 | AN5: =SUM(AB5:AM5)
A6: RT20 Small commercial | B6: 44.388714 | C6: 41.872696 | D6: 49.678165 | E6: 47.362312 | F6: 55.46313 | G6: 55.125421 | H6: 60.644232 | I6: 60.610127 | J6: 60.617571 | K6: 60.701511 | L6: 59.392728 | M6: 58.815791 | N6: =SUM(B6:M6) | O6: 51.505595 | P6: 53.157163 | Q6: 55.364368 | R6: 53.858815 | S6: 56.163029 | T6: 59.867633 | U6: 62.135541 | V6: 62.517573 | W6: 62.15255 | X6: 61.744813 | Y6: 55.499951 | Z6: 57.632969 | AA6: =SUM(O6:Z6) | AB6: 55.109458 | AC6: 55.887713 | AD6: 58.55759 | AE6: 55.287698 | AF6: 57.302576 | AG6: 61.182881 | AH6: 63.263962 | AI6: 63.533791 | AJ6: 62.881261 | AK6: 62.235153 | AL6: 55.534478 | AM6: 57.623439 | AN6: =SUM(AB6:AM6)
A7: RT40 Commercial | B7: 56.013982 | C7: 52.824365 | D7: 61.689786 | E7: 59.597985 | F7: 65.913616 | G7: 64.392244 | H7: 70.139337 | I7: 71.882555 | J7: 67.312952 | K7: 67.752317 | L7: 67.511504 | M7: 66.882825 | N7: =SUM(B7:M7) | O7: 69.08125 | P7: 69.907191 | Q7: 69.669746 | R7: 69.897926 | S7: 70.101411 | T7: 70.070454 | U7: 69.92195 | V7: 69.989398 | W7: 70.029249 | X7: 70.030447 | Y7: 70.034635 | Z7: 69.866343 | AA7: =SUM(O7:Z7) | AB7: 69.942422 | AC7: 69.875018 | AD7: 69.785509 | AE7: 69.900605 | AF7: 69.714698 | AG7: 69.64454 | AH7: 69.594661 | AI7: 69.49901 | AJ7: 69.436043 | AK7: 69.375381 | AL7: 69.2817 | AM7: 69.250413 | AN7: =SUM(AB7:AM7)
A8: RT50 Large commercial | B8: 26.723901 | C8: 26.71247 | D8: 29.77987 | E8: 28.362025 | F8: 30.151229 | G8: 28.210033 | H8: 28.679193 | I8: 30.677402 | J8: 30.252675 | K8: 28.625084 | L8: 28.850286 | M8: 28.627042 | N8: =SUM(B8:M8) | O8: 30.013545 | P8: 30.722989 | Q8: 31.225085 | R8: 31.997182 | S8: 32.676844 | T8: 33.119429 | U8: 33.715263 | V8: 34.299974 | W8: 34.86411 | X8: 35.44622 | Y8: 36.0577 | Z8: 36.661659 | AA8: =SUM(O8:Z8) | AB8: 36.010428 | AC8: 36.201241 | AD8: 36.252398 | AE8: 36.12001 | AF8: 36.15773 | AG8: 36.144627 | AH8: 36.110197 | AI8: 36.108297 | AJ8: 36.093249 | AK8: 36.077564 | AL8: 36.068108 | AM8: 36.056151 | AN8: =SUM(AB8:AM8)
A9: RT60 Street lighting | B9: 2.224345 | C9: 2.309941 | D9: 3.098902 | E9: 3.413243 | F9: 2.798277 | G9: 3.409919 | H9: 3.409214 | I9: 3.413417 | J9: 3.413193 | K9: 3.3377766 | L9: 3.3298319 | M9: 3.3109632 | N9: =SUM(B9:M9) | O9: 3.338606 | P9: 3.334042 | Q9: 3.336247 | R9: 3.331506 | S9: 3.331543 | T9: 3.323479 | U9: 3.317737 | V9: 3.3119 | W9: 3.305376 | X9: 3.297015 | Y9: 3.291095 | Z9: 3.281454 | AA9: =SUM(O9:Z9) | AB9: 3.274143 | AC9: 3.266796 | AD9: 3.258975 | AE9: 3.251757 | AF9: 3.24433 | AG9: 3.236875 | AH9: 3.229543 | AI9: 3.222173 | AJ9: 3.21482 | AK9: 3.207502 | AL9: 3.20019 | AM9: 3.192896 | AN9: =SUM(AB9:AM9)
A10: RT70 Industrial | B10: 20.371321 | C10: 21.088523 | D10: 26.19399 | E10: 24.727332 | F10: 27.726514 | G10: 26.848147 | H10: 28.562426 | I10: 19.707587 | J10: 18.642652 | K10: 18.286687 | L10: 17.674692 | M10: 17.360291 | N10: =SUM(B10:M10) | O10: 15.542829 | P10: 15.371199 | Q10: 16.188143 | R10: 16.500619 | S10: 16.508318 | T10: 16.528448 | U10: 16.214993 | V10: 16.19756 | W10: 16.184073 | X10: 16.154977 | Y10: 16.158884 | Z10: 16.149957 | AA10: =SUM(O10:Z10) | AB10: 16.002632 | AC10: 15.977772 | AD10: 15.957939 | AE10: 15.892773 | AF10: 15.856544 | AG10: 15.816613 | AH10: 15.769857 | AI10: 15.729291 | AJ10: 15.687283 | AK10: 15.644558 | AL10: 15.603189 | AM10: 15.561549 | AN10: =SUM(AB10:AM10)
A11: Total billed sales | B11: =SUM(B5:B10) | C11: =SUM(C5:C10) | D11: =SUM(D5:D10) | E11: =SUM(E5:E10) | F11: =SUM(F5:F10) | G11: =SUM(G5:G10) | H11: =SUM(H5:H10) | I11: =SUM(I5:I10) | ... AN11: =SUM(AN5:AN10)

Sheet Notes
A1: FY2026
A2: Billed sales are actual customer-billed volumes for January to September. October to December are set so the full year equals the financials LE of 3,299.7 GWh, using the register split by rate class and month.
A3: Net generation for January to August is the actual in the financials. September (407.7 GWh) is an estimate read from the System Operations monthly chart and calibrated to the financials net generation, accurate to about 1 GWh; replace it with the actual when issued. October to December are set so the full year equals the financials LE of 4,527.0 GWh, on the financials plan shape.
A4: FY2026 loss on billed sales and net generation is 27.11%.
A6: FY2027 and FY2028
A7: Billed sales are as in the register and Driver Report. Losses follow the seasonal monthly path in the platform assumptions, closing each year at about 27.1%.
